Workbook
Name Gperp: '[1]Discounted Cash Flow (DCF)'!$D$10
Name wacc: '[1]Discounted Cash Flow (DCF)'!$D$9

Sheet Const Challenge
A3: 1. The model provided must be used only as a base for analysis and projection of the financial statements;
A4: 2. The model provides enough historical information for the projections and analysis. If the group believes it has more accurate ways to forecast, we do not discourage their use;
A5: 3. Justifying the premises is critical. Do you think that Burger King's Same-Store Sales will accelerate? Do you think EBITDA margin should expand or contract? Why? At what level should System-wide Sales grow?
A6: 4. All groups receive the same model. With the exception of macroeconomics assumptions, all other assumptions hereby are dummy variables, and the group must elaborate the premises that they find best. The logic behind these premises that will differentiate the groups.

Sheet Model
AG1: *
F2: Assumptions - you should define which value you believe is more appropriate for each assumption - current values are just an example
AG3: *
F4: Not meaningful cells - either historical date is not available or you do not need to forecast the line
AG5: *
E6: 1000 | F6: Inputs are in blue - it is not expected that you change those values
AG7: *
E8: Formulas: It is not required that you change the formulas in the model (unless you desire to change the model structure), but it is important to understand the logic behind them
AG9: *
E10: Watch out for comments across the model, they might provide some hints on how to project and think about some business lines
A12: * | B12: Macro | C12: Unit | D12: 2011 | E12: 2012 | F12: 2013 | G12: 2014 | H12: 2015 | I12: 2016 | J12: 2017 | K12: 2018 | L12: 2019 | M12: 2020 | N12: 2021 | O12: 2022 | P12: 2023 | Q12: 2024 | R12: 2025 | S12: 2026E | T12: 2027E | U12: 2028E | V12: 2029E | W12: 2030E | X12: 2031E | Y12: *
Y13: *
B14: CAD/USD | C14: [USD] | D14: 1.0116286 | E14: 1.0005648 | F14: 0.97079916 | G14: 0.90623159 | H14: 0.78307909 | I14: 0.75633076 | J14: 0.77099301 | K14: 0.77198954 | L14: 0.75352947 | M14: 0.74612565 | N14: 0.79774054 | O14: 0.76895387 | P14: 0.74111047 | Q14: 0.7301 | R14: 0.73 | S14: 0.74 | T14: 0.76 | U14: 0.76 | V14: 0.76 | W14: 0.76 | X14: 0.76 | Y14: *
Y15: *
B16: SOFR | C16: [%] | O16: 0.016359438 | P16: 0.050072691 | Q16: 0.0514844 | R16: 0.04243494 | S16: =AVERAGE(3.53%,3.32%,3.2%,3.16%) -> 0.033025 | T16: =AVERAGE(3.18%,3.16%,3.17%,3.18%) -> 0.031725 | U16: 0.0321 | V16: 0.0321 | W16: 0.0321 | X16: 0.0321 | Y16: *
Y17: *
A18: * | B18: Revenue Build-Up | C18: Unit | D18: 2011 | E18: 2012 | F18: 2013 | G18: 2014 | H18: 2015 | I18: 2016 | J18: 2017 | K18: 2018 | L18: 2019 | M18: 2020 | N18: 2021 | O18: 2022 | P18: 2023 | Q18: 2024 | R18: 2025E | S18: 2026E | T18: 2027E | U18: 2028E | V18: 2029E | W18: 2030E | X18: 2031E | Y18: *
B20: Tim Hortons | Y20: *
Y21: *
B22: Net Revenue | C22: [USD mn] | G22: =G25+G29+G33 -> 3140.8 | H22: =H25+H29+H33 -> 2956.9 | I22: =I25+I29+I33 -> 3001.4 | J22: =J25+J29+J33 -> 3154.6 | K22: =K25+K29+K33 -> 3292.4 | L22: =L25+L29+L33 -> 3344 | M22: =M25+M29+M33 -> 2810 | N22: =N25+N29+N33 -> 3331 | ... X22: =X25+X29+X33 -> 7679.1167 | Y22: *
B23: YoY | C23: [%] | G23: =IFERROR(G22/F22-1,"n.m.") -> n.m. | H23: =IFERROR(H22/G22-1,"n.m.") -> -0.058551961 | I23: =IFERROR(I22/H22-1,"n.m.") -> 0.015049545 | J23: =IFERROR(J22/I22-1,"n.m.") -> 0.051042847 | K23: =IFERROR(K22/J22-1,"n.m.") -> 0.043682242 | L23: =IFERROR(L22/K22-1,"n.m.") -> 0.015672458 | M23: =IFERROR(M22/L22-1,"n.m.") -> -0.159689 | N23: =IFERROR(N22/M22-1,"n.m.") -> 0.18540925 | ... X23: =IFERROR(X22/W22-1,"n.m.") -> 0.11612126 | Y23: *
Y24: *
B25: 1. Supply Chain | C25: [USD mn] | G25: 1844.156 | H25: 1847.4 | I25: 1977.2 | J25: 2151.2 | K25: 2158.043 | L25: 2153.2434 | M25: 1808.699 | N25: 2193 | O25: 2583 | P25: 2678 | Q25: 2708 | R25: =Q25*(1+R26) -> 2908.9336 | S25: =R25*(1+S26) -> 3124.7765 | T25: =S25*(1+T26) -> 3356.6349 | U25: =T25*(1+U26) -> 3605.6972 | V25: =U25*(1+V26) -> 3873.2399 | W25: =V25*(1+W26) -> 4160.6343 | X25: =W25*(1+X26) -> 4469.3534 | Y25: *
B26: YoY | C26: [%] | G26: =IFERROR(G25/F25-1,"n.m.") -> n.m. | H26: =IFERROR(H25/G25-1,"n.m.") -> 0.0017590597 | I26: =IFERROR(I25/H25-1,"n.m.") -> 0.070260907 | J26: =IFERROR(J25/I25-1,"n.m.") -> 0.088003237 | K26: =IFERROR(K25/J25-1,"n.m.") -> 0.0031810216 | L26: =IFERROR(L25/K25-1,"n.m.") -> -0.0022240421 | M26: =IFERROR(M25/L25-1,"n.m.") -> -0.16001183 | N26: =IFERROR(N25/M25-1,"n.m.") -> 0.21247371 | ... Q26: =IFERROR(Q25/P25-1,"n.m.") -> 0.01120239 | R26: 0.0742 | S26: 0.0742 | T26: 0.0742 | U26: 0.0742 | V26: 0.0742 | W26: 0.0742 | X26: 0.0742 | Y26: *
B27: % of Total | C27: [%] | G27: =G25/G$22 -> 0.58716124 | H27: =H25/H$22 -> 0.62477595 | I27: =I25/I$22 -> 0.65875925 | J27: =J25/J$22 -> 0.68192481 | K27: =K25/K$22 -> 0.65546198 | L27: =L25/L$22 -> 0.64391251 | M27: =M25/M$22 -> 0.64366513 | N27: =N25/N$22 -> 0.65836085 | ... X27: =X25/X$22 -> 0.582014
Y28: *
B29: 2. Company Sales | C29: [USD mn] | G29: =G51 -> 344.44398 | H29: =H51 -> 226.9 | I29: =I51 -> 134.9 | J29: =J51 -> 77.7 | K29: =K51 -> 43.156986 | L29: =L51 -> 50.756565 | M29: =M51 -> 67.300994 | N29: =N51 -> 56 | ... X29: =X51 -> 16.138285 | Y29: *
B30: YoY | C30: [%] | G30: =IFERROR(G29/F29-1,"n.m.") -> n.m. | H30: =IFERROR(H29/G29-1,"n.m.") -> -0.34125718 | I30: =IFERROR(I29/H29-1,"n.m.") -> -0.40546496 | J30: =IFERROR(J29/I29-1,"n.m.") -> -0.42401779 | K30: =IFERROR(K29/J29-1,"n.m.") -> -0.44456903 | L30: =IFERROR(L29/K29-1,"n.m.") -> 0.1760915 | M30: =IFERROR(M29/L29-1,"n.m.") -> 0.32595643 | N30: =IFERROR(N29/M29-1,"n.m.") -> -0.16791719 | ... X30: =IFERROR(X29/W29-1,"n.m.") -> 0.042340561 | Y30: *
B31: % of Total | C31: [%] | G31: =G29/G$22 -> 0.10966759 | H31: =H29/H$22 -> 0.076735771 | I31: =I29/I$22 -> 0.044945692 | J31: =J29/J$22 -> 0.024630698 | K31: =K29/K$22 -> 0.013108063 | L31: =L29/L$22 -> 0.015178399 | M31: =M29/M$22 -> 0.023950532 | N31: =N29/N$22 -> 0.016811768 | ... X31: =X29/X$22 -> 0.0021015809 | Y31: *
Y32: *
B33: 3. Franchise Revenues | C33: [USD mn] | G33: 952.2 | H33: 882.6 | I33: 889.3 | J33: 925.7 | K33: 1091.2 | L33: 1140 | M33: 934 | N33: 1082 | O33: 1170 | P33: 1247 | Q33: 1286 | R33: =R38+R43 -> 1357.1218 | S33: =S38+S43 -> 1567.9858 | T33: =T38+T43 -> 1834.4256 | U33: =U38+U43 -> 2045.5083 | V33: =V38+V43 -> 2332.5386 | W33: =W38+W43 -> 2704.0643 | X33: =X38+X43 -> 3193.625 | Y33: *
B34: YoY | C34: [%] | G34: =IFERROR(G33/F33-1,"n.m.") -> n.m. | H34: =IFERROR(H33/G33-1,"n.m.") -> -0.073093888 | I34: =IFERROR(I33/H33-1,"n.m.") -> 0.0075912078 | J34: =IFERROR(J33/I33-1,"n.m.") -> 0.040931069 | K34: =IFERROR(K33/J33-1,"n.m.") -> 0.17878362 | L34: =IFERROR(L33/K33-1,"n.m.") -> 0.044721408 | M34: =IFERROR(M33/L33-1,"n.m.") -> -0.18070175 | N34: =IFERROR(N33/M33-1,"n.m.") -> 0.15845824 | ... X34: =IFERROR(X33/W33-1,"n.m.") -> 0.18104625 | Y34: *
B35: % of Total | C35: [%] | G35: =G33/G$22 -> 0.30317117 | H35: =H33/H$22 -> 0.29848828 | I35: =I33/I$22 -> 0.29629506 | J35: =J33/J$22 -> 0.29344449 | K35: =K33/K$22 -> 0.33142996 | L35: =L33/L$22 -> 0.34090909 | M35: =M33/M$22 -> 0.33238434 | N35: =N33/N$22 -> 0.32482738 | ... X35: =X33/X$22 -> 0.41588442
B36: % of Franchise Sales | C36: [%] | G36: =G33/G$55 -> 0.16192856 | H36: =H33/H$55 -> 0.14969471 | I36: =I33/I$55 -> 0.14494572 | J36: =J33/J$55 -> 0.14107195 | K36: =K33/K$55 -> 0.16086124 | L36: =L33/L$55 -> 0.17234897 | M36: =M33/M$55 -> 0.17446863 | N36: =N33/N$55 -> 0.17488282 | ... X36: =X33/X$55 -> 0.17236188 | Y36: *
Y37: *
B38: 3.1 Franchise and Property Revenues | C38: [USD mn] | M38: 745 | N38: 853 | O38: 904 | P38: 954 | Q38: 987 | R38: =R41*R$55 -> 1044.0018 | S38: =S41*S$55 -> 1213.3406 | T38: =T41*T$55 -> 1413.894 | U38: =U41*U$55 -> 1574.7511 | V38: =V41*V$55 -> 1796.5087 | W38: =W41*W$55 -> 2084.2632 | X38: =X41*X$55 -> 2459.9634 | Y38: *
B39: YoY | C39: [%] | M39: =IFERROR(M38/L38-1,"n.m.") -> n.m. | N39: =IFERROR(N38/M38-1,"n.m.") -> 0.14496644 | O39: =IFERROR(O38/N38-1,"n.m.") -> 0.05978898 | P39: =IFERROR(P38/O38-1,"n.m.") -> 0.055309735 | Q39: =IFERROR(Q38/P38-1,"n.m.") -> 0.034591195 | R39: =IFERROR(R38/Q38-1,"n.m.") -> 0.057752537 | S39: =IFERROR(S38/R38-1,"n.m.") -> 0.1622017 | T39: =IFERROR(T38/S38-1,"n.m.") -> 0.16529027 | ... X39: =IFERROR(X38/W38-1,"n.m.") -> 0.18025564 | Y39: *
B40: % of Total | C40: [%] | M40: =M38/M$22 -> 0.26512456 | N40: =N38/N$22 -> 0.25607926 | O40: =O38/O$22 -> 0.23783215 | P40: =P38/P$22 -> 0.24018127 | Q40: =Q38/Q$22 -> 0.24442793 | R40: =R38/R$22 -> 0.24400711 | S40: =S38/S$22 -> 0.25783889 | T40: =T38/T$22 -> 0.27164953 | ... X40: =X38/X$22 -> 0.32034458
B41: % of Franchise Sales | C41: [%] | M41: =M38/M$55 -> 0.13916395 | N41: =N38/N$55 -> 0.13786973 | O41: =O38/O$55 -> 0.13524835 | P41: =P38/P$55 -> 0.13251911 | Q41: =Q38/Q$55 -> 0.1327505 | R41: 0.1297 | S41: =AVERAGE(M41:R41) -> 0.13454194 | T41: =AVERAGE(N41:S41) -> 0.13377161 | U41: =AVERAGE(O41:T41) -> 0.13308858 | V41: =AVERAGE(P41:U41) -> 0.13272862 | W41: =AVERAGE(Q41:V41) -> 0.13276354 | X41: =AVERAGE(R41:W41) -> 0.13276572 | Y41: *
Y42: *
...

Sheet Summary
C2: QSR | E2: DCF Target
C3: 73.75
E4: Ke | F4: USD/share | G4: Upside
B5: Shares QSR (#mn) | C5: =$N$19 -> 456 | E5: =B93 -> 0.0915 | F5: =J93/$C$5 -> 69.752946 | G5: =F5/$C$3-1 -> -0.054197336
B6: Market Cap (USDmn) | C6: =C5*C3 -> 33630 | E6: =B94 -> 0.0865 | F6: =J94/$C$5 -> 77.286625 | G6: =F6/$C$3-1 -> 0.047954238
C7: BUY | E7: =B95 -> 0.0815 | F7: =J95/$C$5 -> 86.327173 | G7: =F7/$C$3-1 -> 0.17053794
E8: =B96 -> 0.0765 | F8: =J96/$C$5 -> 97.362151 | G8: =F8/$C$3-1 -> 0.32016476
D9: 42716 | E9: =B97 -> 0.0715 | F9: =J97/$C$5 -> 111.11415 | G9: =F9/$C$3-1 -> 0.50663252 | I9: 44907
C11: Unit | D11: 2015 | E11: 2016 | F11: 2017 | G11: 2018 | H11: 2019 | I11: 2020 | J11: 2021 | K11: 2022 | L11: 2023 | M11: 2024 | N11: 2025 | O11: 2026E | P11: 2027E | Q11: 2028E | R11: 2029E | S11: 2030E | T11: 2031E
B12: P/E | C12: x | D12: =IFERROR(D21/D47,"n.m.") -> 39.759841 | E12: =IFERROR(E21/E47,"n.m.") -> 30.150211 | F12: =IFERROR(F21/F47,"n.m.") -> 29.100806 | G12: =IFERROR(G21/G47,"n.m.") -> 20.368811 | H12: =IFERROR(H21/H47,"n.m.") -> 23.763245 | I12: =IFERROR(I21/I47,"n.m.") -> 30.107893 | J12: =IFERROR(J21/J47,"n.m.") -> 21.47503 | K12: =IFERROR(K21/K47,"n.m.") -> 20.931171 | ... T12: =IFERROR(T21/T47,"n.m.") -> 7.4789703
B13: EV/EBITDA | C13: x | D13: =(D21+D56)/D43 -> 16.979472 | E13: =(E21+E56)/E43 -> 16.087154 | F13: =(F21+F56)/F43 -> 19.228792 | G13: =(G21+G56)/G43 -> 16.920407 | H13: =(H21+H56)/H43 -> 18.339803 | I13: =(I21+I56)/I43 -> 22.419206 | J13: =(J21+J56)/J43 -> 18.817146 | K13: =(K21+K56)/K43 -> 18.767236 | ... T13: =(T21+T56)/T43 -> 5.8502444
B14: FCF Yield | C14: % | D14: =D51/D21 -> 0.06164788 | E14: =E51/E21 -> 0.055149763 | F14: =F51/F21 -> 0.045842796 | G14: =G51/G21 -> 0.043619589 | H14: =H51/H21 -> 0.04730333 | I14: =I51/I21 -> 0.028112399 | J14: =J51/J21 -> 0.057537563 | K14: =K51/K21 -> 0.047238983 | ... T14: =T51/T21 -> 0.16510185
B15: Div Yield | C15: % | D15: =D59/D21 -> 0.037124528 | E15: =E59/E21 -> 0.024023385 | F15: =F59/F21 -> 0.0226096 | G15: =G59/G21 -> 0.052109036 | H15: =H59/H21 -> 0.030141655 | I15: =I59/I21 -> 0.033532078 | J15: =J59/J21 -> 0.054163446 | K15: =K59/K21 -> 0.04407839 | ... T15: =T59/T21 -> 0.088116414
B16: ND/EBITDA | C16: x | D16: =D56/D43 -> 5.1809867 | E16: =E56/E43 -> 3.8485958 | F16: =F56/F43 -> 5.1748958 | G16: =G56/G43 -> 5.2085602 | H16: =H56/H43 -> 4.7090743 | I16: =I56/I43 -> 6.2063492 | J16: =J56/J43 -> 5.5985915 | K16: =K56/K43 -> 5.3679417 | ... T16: =T56/T43 -> 0.28322692
B17: EPS | C17: USD | D17: =D47/D19 -> 0.93385685 | E17: =E47/E19 -> 1.5807518 | F17: =F47/F19 -> 2.1126563 | G17: =G47/G19 -> 2.5676511 | H17: =H47/H19 -> 2.6835561 | I17: =I47/I19 -> 2.0297003 | J17: =J47/J19 -> 2.8256073 | K17: =K47/K19 -> 3.0896503 | ... T17: =T47/T19 -> 9.8609831
B18: DVPS | C18: USD | D18: =D59/D19 -> 1.3784337 | E18: =E59/E19 -> 1.1449545 | F18: =F59/F19 -> 1.3900382 | G18: =G59/G19 -> 2.7253026 | H18: =H59/H19 -> 1.9221333 | I18: =I59/I19 -> 2.0491453 | J18: =J59/J19 -> 3.2866379 | K18: =K59/K19 -> 2.8505495 | ... T18: =T59/T19 -> 6.4985856
B19: Number of shares - Diluted | C19: # | D19: 475.975 | E19: 469.975 | F19: 477.325 | G19: 472.975 | H19: 468.75 | I19: 468 | J19: 464 | K19: 455 | L19: 456 | M19: 454 | N19: 456 | O19: =N19 -> 456 | P19: =O19 -> 456 | Q19: =P19 -> 456 | R19: =Q19 -> 456 | S19: =R19 -> 456 | T19: =S19 -> 456
B20: Stock Price EoP | C20: USD | D20: 37.13 | E20: 47.66 | F20: 61.48 | G20: 52.3 | H20: 63.77 | I20: 61.11 | J20: 60.68 | K20: 64.67 | L20: 78.13 | M20: 65.18 | N20: 68.23 | O20: =$C$3 -> 73.75 | P20: =$C$3 -> 73.75 | Q20: =$C$3 -> 73.75 | R20: =$C$3 -> 73.75 | S20: =$C$3 -> 73.75 | T20: =$C$3 -> 73.75
B21: Mkt Cap EoP | C21: USD mn | D21: =D20*D19 -> 17672.952 | E21: =E20*E19 -> 22399.008 | F21: =F20*F19 -> 29345.941 | G21: =G20*G19 -> 24736.592 | H21: =H20*H19 -> 29892.188 | I21: =I20*I19 -> 28599.48 | J21: =J20*J19 -> 28155.52 | K21: =K20*K19 -> 29424.85 | ... T21: =T20*T19 -> 33630
C23: Unit | D23: 2015 | E23: 2016 | F23: 2017 | G23: 2018 | H23: 2019 | I23: 2020 | J23: 2021 | K23: 2022 | L23: 2023 | M23: 2024 | N23: 2025 | O23: 2026E | P23: 2027E | Q23: 2028E | R23: 2029E | S23: 2030E | T23: 2031E | V23: CAGR 26 - 29
B24: Net Revenue | C24: USD mn | D24: =Model!H432 -> 4052.2 | E24: =Model!I432 -> 4145.8 | F24: =Model!J432 -> 4576.1 | G24: =Model!K432 -> 5357 | H24: =Model!L432 -> 5603 | I24: =Model!M432 -> 4968 | J24: =Model!N432 -> 5739 | K24: =Model!O432 -> 6505 | ... T24: =Model!X432 -> 23712.646 | V24: =(R24/O24)^(1/3)-1 -> 0.16609422
B25: YoY | C25: % | D25: =IFERROR(D24/C24-1,"n.m") -> n.m | E25: =IFERROR(E24/D24-1,"n.m") -> 0.023098564 | F25: =IFERROR(F24/E24-1,"n.m") -> 0.10379179 | G25: =IFERROR(G24/F24-1,"n.m") -> 0.17064749 | H25: =IFERROR(H24/G24-1,"n.m") -> 0.045921225 | I25: =IFERROR(I24/H24-1,"n.m") -> -0.11333214 | J25: =IFERROR(J24/I24-1,"n.m") -> 0.15519324 | K25: =IFERROR(K24/J24-1,"n.m") -> 0.13347273 | ... T25: =IFERROR(T24/S24-1,"n.m") -> 0.18218268
B27: 1. Company Restaurant Sales | C27: USD mn | J27: =Model!N467 -> 184 | K27: =Model!O467 -> 236 | L27: =Model!P467 -> 273 | M27: =Model!Q467 -> 1591 | N27: =Model!R467 -> 7014.9889 | O27: =Model!S467 -> 3250.3638 | P27: =Model!T467 -> 4987.2953 | Q27: =Model!U467 -> 6146.6575 | ... T27: =Model!X467 -> 12161.727 | V27: =(R27/O27)^(1/3)-1 -> 0.3297614
B28: YoY | C28: % | J28: =IFERROR(J27/I27-1,"n.m") -> n.m | K28: =IFERROR(K27/J27-1,"n.m") -> 0.2826087 | L28: =IFERROR(L27/K27-1,"n.m") -> 0.15677966 | M28: =IFERROR(M27/L27-1,"n.m") -> 4.8278388 | N28: =IFERROR(N27/M27-1,"n.m") -> 3.4091696 | O28: =IFERROR(O27/N27-1,"n.m") -> -0.53665446 | P28: =IFERROR(P27/O27-1,"n.m") -> 0.53438065 | Q28: =IFERROR(Q27/P27-1,"n.m") -> 0.2324631 | ... T28: =IFERROR(T27/S27-1,"n.m") -> 0.26769366
B29: % of Total | C29: % | J29: =J27/J$24 -> 0.032061335 | K29: =K27/K$24 -> 0.036279785 | L29: =L27/L$24 -> 0.038877813 | M29: =M27/M$24 -> 0.18926957 | N29: =N27/N$24 -> 0.51491063 | O29: =O27/O$24 -> 0.29932692 | P29: =P27/P$24 -> 0.37862621 | Q29: =Q27/Q$24 -> 0.4104686 | ... T29: =T27/T$24 -> 0.51287939
B31: 2. Supply Chain Sales | C31: USD mn | J31: =Model!N471 -> 2193 | K31: =Model!O471 -> 2583 | L31: =Model!P471 -> 2678 | M31: =Model!Q471 -> 2708 | N31: =Model!R471 -> 2908.9336 | O31: =Model!S471 -> 3124.7765 | P31: =Model!T471 -> 3356.6349 | Q31: =Model!U471 -> 3605.6972 | ... T31: =Model!X471 -> 4469.3534 | V31: =(R31/O31)^(1/3)-1 -> 0.0742
B32: YoY | C32: % | J32: =IFERROR(J31/I31-1,"n.m") -> n.m | K32: =IFERROR(K31/J31-1,"n.m") -> 0.17783858 | L32: =IFERROR(L31/K31-1,"n.m") -> 0.036778939 | M32: =IFERROR(M31/L31-1,"n.m") -> 0.01120239 | N32: =IFERROR(N31/M31-1,"n.m") -> 0.0742 | O32: =IFERROR(O31/N31-1,"n.m") -> 0.0742 | P32: =IFERROR(P31/O31-1,"n.m") -> 0.0742 | Q32: =IFERROR(Q31/P31-1,"n.m") -> 0.0742 | ... T32: =IFERROR(T31/S31-1,"n.m") -> 0.0742
B33: % of Total | C33: % | J33: =J31/J$24 -> 0.38212232 | K33: =K31/K$24 -> 0.39707917 | L33: =L31/L$24 -> 0.38137283 | M33: =M31/M$24 -> 0.32215084 | N33: =N31/N$24 -> 0.21352006 | O33: =O31/O$24 -> 0.28776155 | P33: =P31/P$24 -> 0.25482949 | Q33: =Q31/Q$24 -> 0.24078542 | ... T33: =T31/T$24 -> 0.18847974
B35: 3. Franchise Revenues | C35: USD mn | J35: =Model!N475 -> 3357 | K35: =Model!O475 -> 3684 | L35: =Model!P475 -> 4073 | M35: =Model!Q475 -> 4101.3 | N35: =Model!R475 -> 3697.1044 | O35: =Model!S475 -> 4481.0938 | P35: =Model!T475 -> 4825.4764 | Q35: =Model!U475 -> 5219.7028 | ... T35: =Model!X475 -> 7078.8902 | V35: =(R35/O35)^(1/3)-1 -> 0.083468485
B36: YoY | C36: % | J36: =IFERROR(J35/I35-1,"n.m") -> n.m | K36: =IFERROR(K35/J35-1,"n.m") -> 0.0974084 | L36: =IFERROR(L35/K35-1,"n.m") -> 0.10559175 | M36: =IFERROR(M35/L35-1,"n.m") -> 0.0069481954 | N36: =IFERROR(N35/M35-1,"n.m") -> -0.098553054 | O36: =IFERROR(O35/N35-1,"n.m") -> 0.212055 | P36: =IFERROR(P35/O35-1,"n.m") -> 0.076852338 | Q36: =IFERROR(Q35/P35-1,"n.m") -> 0.0816969 | ... T36: =IFERROR(T35/S35-1,"n.m") -> 0.12337205
B37: % of Total | C37: % | J37: =J35/J$24 -> 0.58494511 | K37: =K35/K$24 -> 0.56633359 | L37: =L35/L$24 -> 0.58003418 | M37: =M35/M$24 -> 0.4879015 | N37: =N35/N$24 -> 0.27137296 | O37: =O35/O$24 -> 0.41266519 | P37: =P35/P$24 -> 0.36634122 | Q37: =Q35/Q$24 -> 0.34856735 | ... T37: =T35/T$24 -> 0.29852806
B39: 4. Others | C39: USD mn | J39: =J24-J27-J31-J35 -> 5 | K39: =K24-K27-K31-K35 -> 2 | L39: =L24-L27-L31-L35 -> -2 | M39: =M24-M27-M31-M35 -> 5.7 | N39: =N24-N27-N31-N35 -> 2.675 | O39: =O24-O27-O31-O35 -> 2.675 | P39: =P24-P27-P31-P35 -> 2.675 | Q39: =Q24-Q27-Q31-Q35 -> 2.675 | ... T39: =T24-T27-T31-T35 -> 2.675 | V39: =IFERROR((R39/O39)^(1/3)-1,"n.m.") -> -4.5330406e-13
B40: YoY | C40: % | J40: =IFERROR(J39/I39-1,"n.m") -> n.m | K40: =IFERROR(K39/J39-1,"n.m") -> -0.6 | L40: =IFERROR(L39/K39-1,"n.m") -> -2 | M40: =IFERROR(M39/L39-1,"n.m") -> -3.85 | N40: =IFERROR(N39/M39-1,"n.m") -> -0.53070175 | O40: =IFERROR(O39/N39-1,"n.m") -> -3.3995029e-13 | P40: =IFERROR(P39/O39-1,"n.m") -> -1.6999735e-12 | Q40: =IFERROR(Q39/P39-1,"n.m") -> 1.3600232e-12 | ... T40: =IFERROR(T39/S39-1,"n.m") -> -3.3995029e-13
B41: % of Total | C41: % | J41: =J39/J$24 -> 0.00087123192 | K41: =K39/K$24 -> 0.0003074558 | L41: =L39/L$24 -> -0.00028481914 | M41: =M39/M$24 -> 0.00067808708 | N41: =N39/N$24 -> 0.00019634898 | O41: =O39/O$24 -> 0.0002463415 | P41: =P39/P$24 -> 0.00020308104 | Q41: =Q39/Q$24 -> 0.00017863424 | ... T41: =T39/T$24 -> 0.000112809
B43: Adj. EBITDA | C43: USD mn | D43: =Model!H620 -> 1497.9 | E43: =Model!I620 -> 1830.2 | F43: =Model!J620 -> 2088.1 | G43: =Model!K620 -> 2112.1 | H43: =Model!L620 -> 2193 | I43: =Model!M620 -> 1764 | J43: =Model!N620 -> 2130 | K43: =Model!O620 -> 2196 | ... T43: =Model!X620 -> 6040.9366 | V43: =(R43/O43)^(1/3)-1 -> 0.13921654
B44: YoY | C44: % | D44: =IFERROR(D43/C43-1,"n.m") -> n.m | E44: =IFERROR(E43/D43-1,"n.m") -> 0.22184391 | F44: =IFERROR(F43/E43-1,"n.m") -> 0.14091356 | G44: =IFERROR(G43/F43-1,"n.m") -> 0.011493702 | H44: =IFERROR(H43/G43-1,"n.m") -> 0.038303111 | I44: =IFERROR(I43/H43-1,"n.m") -> -0.19562244 | J44: =IFERROR(J43/I43-1,"n.m") -> 0.20748299 | K44: =IFERROR(K43/J43-1,"n.m") -> 0.030985915 | ... T44: =IFERROR(T43/S43-1,"n.m") -> 0.20717161
B45: EBITDA Margin | C45: % | D45: =D43/D$24 -> 0.36965105 | E45: =E43/E$24 -> 0.44145883 | F45: =F43/F$24 -> 0.45630559 | G45: =G43/G$24 -> 0.39426918 | H45: =H43/H$24 -> 0.39139747 | I45: =I43/I$24 -> 0.35507246 | J45: =J43/J$24 -> 0.3711448 | K45: =K43/K$24 -> 0.33758647 | ... T45: =T43/T$24 -> 0.25475591
B47: Adj. Net Income | C47: USD mn | D47: =Model!H649 -> 444.49251 | E47: =Model!I649 -> 742.91383 | F47: =Model!J649 -> 1008.4237 | G47: =Model!K649 -> 1214.4348 | H47: =Model!L649 -> 1257.9169 | I47: =Model!M649 -> 949.89976 | J47: =Model!N649 -> 1311.0818 | K47: =Model!O649 -> 1405.7909 | ... T47: =Model!X649 -> 4496.6083 | V47: =(R47/O47)^(1/3)-1 -> 0.18955582
B48: YoY | C48: % | D48: =IFERROR(D47/C47-1,"n.m") -> n.m | E48: =IFERROR(E47/D47-1,"n.m") -> 0.67137535 | F48: =IFERROR(F47/E47-1,"n.m") -> 0.35738979 | G48: =IFERROR(G47/F47-1,"n.m") -> 0.20429026 | H48: =IFERROR(H47/G47-1,"n.m") -> 0.035804426 | I48: =IFERROR(I47/H47-1,"n.m") -> -0.24486288 | J48: =IFERROR(J47/I47-1,"n.m") -> 0.38023171 | K48: =IFERROR(K47/J47-1,"n.m") -> 0.07223739 | ... T48: =IFERROR(T47/S47-1,"n.m") -> 0.217019
B49: Net Margin | C49: % | D49: =D47/D$24 -> 0.10969165 | E49: =E47/E$24 -> 0.17919674 | F49: =F47/F$24 -> 0.22036749 | G49: =G47/G$24 -> 0.22670054 | H49: =H47/H$24 -> 0.22450775 | I49: =I47/I$24 -> 0.19120366 | J49: =J47/J$24 -> 0.22845126 | K49: =K47/K$24 -> 0.21610928 | ... T49: =T47/T$24 -> 0.18962912
...

Sheet Glossary
B2: Glossary | C2: Definition
B3: BoP | C3: Beginning of Period
B4: Capex | C4: Capital Expenditures
B5: CFF | C5: Cash flow from financing activities
B6: CFI | C6: Cash Flow from from investing activities
B7: CFO | C7: Cash Flow from operating activities
B8: D&A | C8: Depreciation and amortization
B9: DVPS | C9: Dividends per share
B10: EoP | C10: End of Period
B11: EPS | C11: Earnings per Share
B12: EV | C12: Enterprise Value
B13: FCF | C13: Free cash flow
... B27: YoY | C27: Year-over-year

Sheet WACC
B2: WACC
D3: r
A4: x | B4: WACC
B5: WACC = (% Equity x Cost of Equity) + (% Debt x Cost of Debt x (1 -Tax rate))
B6: Cost of Equity = Risk Free Rate + (Beta x (Expected Market Return - Risk Free Rate)) | M6: MOODY'S/Fitch
L7: EBIT/Juros | M7: Rating is | N7: Spread is
L8: -100000 | M8: D2/D | N8: 0.2
B9: Custo do capital próprio | E9: =E10+E12*E13 -> 0.20673416 | L9: 0.2 | M9: C2/C | N9: 0.175
B10: Taxa Livre de Risco: | E10: 0.1356 | F10: https://tradingeconomics.com/brazil/government-bond-yield | L10: 0.65 | M10: Ca2/CC | N10: 0.1578
B11: Risco País: | E11: 0.0334 | F11: http://pages.stern.nyu.edu/~adamodar/New_Home_Page/datafile/ctryprem.html | L11: 0.8 | M11: Caa/CCC | N11: 0.1157
B12: Beta: | E12: ='[1]Cálculo Beta'!B9 -> 0.92743364 | F12: http://www.stern.nyu.edu/~adamodar/pc/datasets/betaGlobal.xls | L12: 1.25 | M12: B3/B- | N12: 0.0737
B13: Prêmio Mercado: | E13: 0.0767 | F13: http://pages.stern.nyu.edu/~adamodar/New_Home_Page/datafile/ctryprem.html | L13: 1.5 | M13: B2/B | N13: 0.0526
B14: Equity/(Debt + Equity) | E14: =E23/(E23+E24) -> 0.40634634 | F14: PL/(Divida Bruta+PL)
B15: Custo da dívida | E15: =E16*(1-E17) -> 0.0792 | L15: 1.75 | M15: B1/B+ | N15: 0.0455
B16: Taxa de juros da dívida | E16: 0.12 | F16: Taxa de juros que a empresa paga | L16: 2 | M16: Ba2/BB | N16: 0.0313
B17: Impostos | E17: 0.34 | F17: Impostos/EBIT ou 34% | L17: 2.25 | M17: Ba1/BB+ | N17: 0.0242
B18: Debt/(Debt + Equity) | E18: =E24/(E23+E24) -> 0.59365366 | F18: Divida Bruta/(PL+DIVIDA BRUTA) | L18: 2.5 | M18: Baa2/BBB | N18: 0.02
L19: 3 | M19: A3/A- | N19: 0.0162
B20: WACC Consolidado | E20: =E9*E14+E15*E18 -> 0.13102304 | L20: 4.25 | M20: A2/A | N20: 0.0142
L21: 5.5 | M21: A1/A+ | N21: 0.0123
L22: 6.5 | M22: Aa2/AA | N22: 0.0085
B23: Equity (PL) | E23: =Model!G703 -> 4323.2 | L23: 8.50 | M23: Aaa/AAA | N23: 0.0069
A24: x | B24: Debt (Dív. Bruta) | E24: 6316
B35: 2025 | C35: 2026 | D35: 2027 | E35: 2028 | F35: 2029 | G35: 2030 | H35: 2031 | I35: 2011 | J35: 2012 | K35: 2013 | L35: 2014 | M35: 2015 | N35: 2016 | O35: 2017 | P35: 2018 | Q35: 2019 | R35: 2020 | S35: 2021 | T35: 2022 | U35: 2023 | V35: 2024 | W35: 2025 | X35: 2026E | Y35: 2027E | Z35: 2028E | AA35: 2029E | AB35: 2030E | AC35: 2031E
B36: TH | C36: =26%*F36 -> 104 | D36: =20%*F36 -> 80 | E36: 98 | F36: 400 | I36: =Model!D59 -> 3713 | J36: =Model!E61 -> 226 | K36: =Model!F61 -> 159 | L36: =Model!G61 -> 147 | M36: =Model!H61 -> 144 | N36: =Model!I61 -> 195 | O36: =Model!J61 -> 138 | P36: =Model!K61 -> 98 | Q36: =Model!L61 -> 86 | ... AC36: =Model!X61 -> 71.442
B37: PKL | C37: =23%*F36 -> 92 | D37: =29%*F36 -> 116 | E37: 98 | J37: =Model!E177 -> 2104 | K37: =Model!F177 -> 121 | L37: =Model!G177 -> 154 | M37: =Model!H177 -> 160 | N37: =Model!I177 -> 149 | O37: =Model!J177 -> 204 | P37: =Model!K177 -> 210 | Q37: =Model!L177 -> 214 | ... AC37: =Model!X177 -> 77.759496
B38: BK | C38: 4 | D38: 4 | E38: 4 | S38: =Model!N120 -> 7433 | T38: =Model!O120 -> -44 | U38: =Model!P120 -> -245 | V38: =Model!Q120 -> -62 | W38: =Model!R120 -> -57 | X38: =Model!S120 -> 4 | Y38: =Model!T120 -> 4 | Z38: =Model!U120 -> 4 | ... AC38: =Model!X120 -> 20
B39: FH | C39: 200 | D39: 200 | E39: 200 | S39: =Model!N234 -> 1213 | T39: =Model!O234 -> 29 | U39: =Model!P234 -> 23 | V39: =Model!Q234 -> 80 | W39: =Model!R234 -> 104 | X39: =Model!S234 -> 200 | Y39: =Model!T234 -> 200 | Z39: =Model!U234 -> 200 | ... AC39: =Model!X234 -> 160.847
B40: TH INT | C40: 275 | D40: 275 | E40: 275 | S40: =Model!N336 -> 720 | T40: =Model!O336 -> 361 | U40: =Model!P336 -> 227 | V40: =Model!Q336 -> 196 | W40: =Model!R336 -> 142 | X40: =Model!S336 -> 375 | Y40: =Model!T336 -> 375 | Z40: =Model!U336 -> 375 | ... AC40: =Model!X336 -> 335.291
B41: PKL INT | C41: 375 | D41: 375 | E41: 375 | S41: =Model!N374 -> 674 | T41: =Model!O374 -> 182 | U41: =Model!P374 -> 321 | V41: =Model!Q374 -> 282 | W41: =Model!R374 -> 376 | X41: =Model!S374 -> 475 | Y41: =Model!T374 -> 475 | Z41: =Model!U374 -> 475 | ... AC41: =Model!X374 -> 877.13234
B42: BK INT | C42: 275 | D42: 275 | E42: 275 | S42: =Model!N355 -> 11814 | T42: =Model!O355 -> -234 | U42: =Model!P355 -> 660 | V42: =Model!Q355 -> 410 | W42: =Model!R355 -> 225 | X42: =Model!S355 -> 475 | Y42: =Model!T355 -> 475 | Z42: =Model!U355 -> 475 | ... AC42: =Model!X355 -> 455.1261
B43: FH INT | C43: 75 | D43: 75 | E43: 75 | U43: =Model!P393 -> 17 | V43: =Model!Q393 -> 9 | W43: =Model!R393 -> 21 | X43: =Model!S393 -> 75 | Y43: =Model!T393 -> 75 | Z43: =Model!U393 -> 75 | AA43: =Model!V393 -> 108.8 | AB43: =Model!W393 -> 152.32 | AC43: =Model!X393 -> 213.248
B44: TH CH | C44: 100 | D44: 100 | E44: 100
B45: PKL CH | C45: 100 | D45: 100 | E45: 100
B46: BK CH | C46: 200 | D46: 200 | E46: 200
B47: FH CH | C47: 0 | D47: 0 | E47: 0
B48: EUA | C48: =C36+C37+C38+C39 -> 400 | D48: =D36+D37+D38+D39 -> 400 | E48: =E36+E37+E38+E39 -> 400
B49: RESTO DO MUNDO | C49: =SUM(C40:C47) -> 1400 | D49: =SUM(D40:D47) -> 1400 | E49: =SUM(E40:E47) -> 1400
B50: TOTAL | C50: =C48+C49 -> 1800 | D50: =D48+D49 -> 1800 | E50: =E48+E49 -> 1800 | F50: =Model!V61+Model!V120+Model!V181+Model!V234+Model!V285+Model!V336+Model!V355+Model!V374+Model!V393 -> 1939.18 | G50: =Model!W61+Model!W120+Model!W181+Model!W234+Model!W285+Model!W336+Model!W355+Model!W374+Model!W393 -> 2163.2201 | H50: =Model!X61+Model!X120+Model!X181+Model!X234+Model!X285+Model!X336+Model!X355+Model!X374+Model!X393 -> 2449.7604 | I50: =SUM(I36:I49) -> 3713 | J50: =SUM(J36:J49) -> 2330 | K50: =SUM(K36:K49) -> 280 | L50: =SUM(L36:L49) -> 301 | M50: =SUM(M36:M49) -> 304 | N50: =SUM(N36:N49) -> 344 | O50: =SUM(O36:O49) -> 342 | P50: =SUM(P36:P49) -> 308 | ... AC50: =SUM(AC36:AC49) -> 2210.8459
B51: =Model!R59+Model!R118+Model!R175+Model!R232+Model!R334+Model!R353+Model!R372+Model!R391 -> 33003 | C51: =B51+SUM(C36:C47) -> 34803 | D51: =C51+SUM(D36:D47) -> 36603 | E51: =D51+SUM(E36:E47) -> 38403 | F51: =E51+F50 -> 40342.18 | G51: =F51+G50 -> 42505.4 | H51: =G51+H50 -> 44955.161 | I51: =I50 -> 3713 | J51: =J50+I51 -> 6043 | K51: =K50+J51 -> 6323 | L51: =L50+K51 -> 6624 | M51: =M50+L51 -> 6928 | N51: =N50+M51 -> 7272 | O51: =O50+N51 -> 7614 | P51: =P50+O51 -> 7922 | Q51: =Q50+P51 -> 8222 | ... AC51: =AC50+AB51 -> 44301.601
...

Sheet Restaurant Sector - 4Q2025
A1: Company | B1: Ticker | C1: Market Cap | D1: P/E | E1: P/B | F1: P/EBIT | G1: P/EBITDA | H1: Dividend Yield % | I1: ROA % | J1: ROE % | K1: ROIC % | L1: Gross Margin % | M1: Operating Margin % | N1: Net Margin % | O1: EBIT | P1: EBITDA | Q1: 52W Range
A2: McDonald's Corporation | B2: MCD | C2: 222616.03 | D2: 26.15 | G2: 15.25 | H2: 0.0236 | I2: 13.51 | L2: 57.41 | M2: 45.07 | N2: 31.85 | O2: 12425000000 | P2: 14594000 | Q2: $283.47 - $341.75
A3: Starbucks Corporation | B3: SBUX | C3: 107925.89 | D3: 78.94 | G3: 20.37 | H3: 0.0268 | I3: 6.87 | L3: 22.17 | M3: 9.26 | N3: 3.63 | O3: 3549100000 | P3: 5297300 | Q3: $75.50 - $104.82
A4: Chipotle Mexican Grill, Inc. | B4: CMG | C4: 42967.42 | D4: 28.5 | E4: 14.97 | G4: 18.04 | I4: 13.88 | J4: 47.36 | L4: 40.1 | M4: 15.21 | N4: 12.88 | O4: 1988735000 | P4: 2381940 | Q4: $29.75 - $58.42
A5: Yum! Brands, Inc. | B5: YUM | C5: 43719.22 | D5: 28.37 | G5: 15.02 | H5: 0.0189 | I5: 22.65 | L5: 46.16 | M5: 31.93 | N5: 18.98 | O5: 2455000000 | P5: 2910000 | Q5: $137.33 - $169.39
A6: Restaurant Brands International Inc. | B6: QSR | C6: 33859.06 | D6: 28.24 | E6: 7.08 | G6: 12.12 | H6: 0.035 | I6: 6.2 | J6: 24.01 | L6: 33.85 | M6: 26.44 | N6: 8.23 | O6: 2158000000 | P6: 2794000 | Q6: $58.71 - $75.57
A7: Domino's Pizza, Inc. | B7: DPZ | C7: 12535.68 | D7: 21.23 | G7: 12.42 | H7: 0.0211 | I7: 34.56 | L7: 28.62 | M7: 18.06 | N7: 12.18 | O7: 857138000 | P7: 1009170 | Q7: $370.70 - $499.08
A8: Yum China Holdings, Inc. | B8: YUMC | C8: 18881.25 | D8: 21.35 | E8: 3.53 | G8: 10.64 | H8: 0.022 | I8: 7.57 | J8: 16.03 | L8: 20.56 | M8: 7.16 | N8: 7.88 | O8: 1474000000 | P8: 1775000 | Q8: $41.00 - $58.39
A9: Darden Restaurants, Inc. | B9: DRI | C9: 23703.58 | D9: 21.38 | E9: 11.29 | G9: 11.93 | H9: 0.0299 | I9: 7.2 | J9: 54.1 | L9: 21.55 | M9: 10.39 | N9: 8.92 | O9: 766300000 | P9: 1987700 | Q9: $169.00 - $228.27
A10: Texas Roadhouse, Inc. | B10: TXRH | C10: 11232.93 | D10: 27.84 | E10: 7.67 | G10: 16.48 | H10: 0.0178 | I10: 8.81 | J10: 29.02 | L10: 16.53 | M10: 6.53 | N10: 6.9 | O10: 66244000 | P10: 681730 | Q10: $148.73 - $199.99
A11: Wingstop Inc. | B11: WING | C11: 5151.13 | D11: 29.85 | G11: 23.71 | H11: 0.063 | I11: 17.04 | L11: 48.68 | M11: 27.19 | N11: 25.01 | O11: 202108000 | P11: 217230 | Q11: $184.77 - $388.14
A13: Company | B13: Ticker | C13: Market Cap | D13: P/E | E13: P/B | F13: P/EBIT | G13: P/EBITDA | H13: Dividend Yield | I13: ROA | J13: ROE | K13: ROIC | L13: Gross Margin | M13: Operating Margin | N13: Net Margin | O13: EBIT | P13: EBITDA | Q13: 52W Range | R13: Business Leverage
A14: McDONALD’S CORPORATION | B14: MCD | C14: 217119140423 | D14: 25.36 | F14: 17.52 | G14: 16.9 | H14: 0.0235 | I14: 0.1493 | K14: 0.2717 | M14: 0.461 | N14: 0.3185 | O14: 12393000000 | P14: 12850000000 | Q14: 276.53 – 326.32 | R14: 3.1069261
A15: Starbucks Corporation | B15: SBUX | C15: 96931646086 | D15: 70.81 | F15: 35.82 | H15: 0.0288 | I15: 0.0427 | K15: 0.3786 | M15: 0.0718 | N15: 0.0363 | O15: 2705700000 | Q15: 75.50 – 117.46
A16: CHIPOTLE MEXICAN GRILL, INC. | B16: CMG | C16: 48189651000 | D16: 31.38 | E16: 17.02 | F16: 24.89 | G16: 20.98 | I16: 0.1688 | J16: 0.4736 | M16: 0.1623 | N16: 0.1288 | O16: 1935798000 | P16: 2297180000 | Q16: 29.75 – 61.16
A17: YUM! BRANDS, INC. | B17: YUM | C17: 41818349729 | D17: 26.82 | F17: 16.25 | G17: 15.04 | H17: 0.0188 | I17: 0.2089 | K17: 0.5564 | M17: 0.3134 | N17: 0.1898 | O17: 2574000000 | P17: 2780000000 | Q17: 122.13 – 163.30 | R17: 4.0291367
A18: RESTAURANT BRANDS INTERNATIONAL INC. | B18: QSR | C18: 21586774875 | D18: 28.78 | E18: 5.94 | F18: 9.8 | H18: 0.0363 | I18: 0.0299 | J18: 0.2224 | K18: 0.1008 | M18: 0.2334 | N18: 0.0795 | O18: 2202000000 | Q18: 58.71 – 73.70
A19: DARDEN RESTAURANTS INC | B19: DRI | C19: 20117129726 | D19: 17.92 | E19: 9.67 | F19: 13.77 | G19: 10.06 | H19: 0.0332 | I19: 0.0882 | J19: 0.5407 | K19: 0.3227 | L19: 0.2017 | M19: 0.1161 | N19: 0.0892 | O19: 1460600000 | P19: 2000500000 | Q19: 159.67 – 228.27 | R19: 0.95726068
A20: Yum China Holdings, Inc. | B20: YUMC | C20: 16856824829 | D20: 18.15 | E20: 3.13 | F20: 13.07 | G20: 9.7 | H20: 0.0101 | I20: 0.0848 | J20: 0.1673 | M20: 0.1093 | N20: 0.0787 | O20: 1290000000 | P20: 1738000000 | Q20: 41.00 – 53.99
A21: Domino’s Pizza, Inc. | B21: DPZ | C21: 14311113325 | D21: 23.78 | F21: 15 | G21: 14.66 | H21: 0.0164 | I21: 0.3485 | L21: 0.3995 | M21: 0.1931 | N21: 0.1218 | O21: 953974000 | P21: 976483000 | Q21: 392.89 – 500.55 | R21: -0.11364765
A22: TEXAS ROADHOUSE, INC. | B22: TXRH | C22: 11035868871 | D22: 37.94 | E22: 7.55 | F22: 23.25 | G22: 16.2 | H22: 0.0162 | I22: 0.0863 | J22: 0.2063 | K22: 0.3223 | M22: 0.0808 | N22: 0.0495 | O22: 474740000 | P22: 681380000 | Q22: 148.73 – 199.99 | R22: -0.12431976
A23: CAVA Group, Inc. | B23: CAVA | C23: 7000122742 | D23: 109.82 | E23: 8.98 | F23: 126.62 | G23: 54.29 | I23: 0.0504 | J23: 0.0864 | L23: 0.1952 | M23: 0.0469 | N23: 0.054 | O23: 55285000 | P23: 128946000 | Q23: 43.41 – 144.49

Sheet Metadata
A1: RESTAURANT SECTOR FINANCIAL ANALYSIS - 4Q2025 | B1: TTM (Trailing Twelve Months)
A3: Data Collection Date | B3: 2026-03-19 15:06:08
A4: Analysis Period | B4: TTM ending 4Q2025
A5: Currency | B5: USD (millions for absolute values)
A7: METRIC DEFINITIONS
A9: VALUATION METRICS
A10: P/E Ratio | B10: Price-to-Earnings ratio
A11: P/B Ratio | B11: Price-to-Book ratio
A12: P/EBIT | B12: Market Cap / EBIT
A13: P/EBITDA | B13: Market Cap / EBITDA
A14: Dividend Yield % | B14: Annual dividend per share as % of stock price
A16: PROFITABILITY METRICS
A17: ROA % | B17: Return on Assets (%)
A18: ROE % | B18: Return on Equity (%)
A19: ROIC % | B19: Return on Invested Capital (%)
A21: MARGIN METRICS (%)
A22: Gross Margin % | B22: (Gross Profit / Revenue) × 100
A23: Operating Margin % | B23: (Operating Income / Revenue) × 100
A24: Net Margin % | B24: (Net Income / Revenue) × 100
A26: ABSOLUTE METRICS (USD Millions)
A27: EBIT | B27: Earnings Before Interest and Taxes
A28: EBITDA | B28: Earnings Before Interest, Taxes, Depreciation & Amortization
A29: Market Cap | B29: Current market capitalization
A31: DATA SOURCES
A32: Primary | B32: Yahoo Finance API (TTM financial data)
A33: Secondary | B33: SEC EDGAR 10-K and 10-Q filings
A35: DATA QUALITY NOTES
A36: Blank Cells | B36: Data unavailable or unreliable - NOT estimated
A37: Time Period | B37: All metrics standardized to TTM ending 4Q2025
A38: Currency | B38: All monetary values in USD; absolute metrics in millions
A39: Validation | B39: Cross-referenced against multiple sources; SEC filings prioritized
A41: KNOWN LIMITATIONS
A42: ROIC | B42: Requires detailed capital structure analysis - left blank
A43: EBITDA | B43: Calculated from available data; verify against 10-K for accuracy
A44: Market Cap | B44: Snapshot as of data collection date
A45: FX Risk | B45: International companies affected by forex rates in reporting

Sheet Scenario_2026
A1: Assunção / Driver | B1: Sheet | C1: Cell | D1: Valor anterior | E1: Valor novo (link) | F1: Justificativa | G1: Fonte (URL / nota)
A2: CAD mais fraco em 2026E por risco Canadá/tarifas -> piora translação de TH; conservador vs 0.74 | B2: Model | C2: S14 | D2: 0.74 | E2: =[3]Model!S14 -> 0.72 | F2: CAD mais fraco em 2026E por risco Canadá/tarifas -> piora translação de TH; conservador vs 0.74 | G2: (nota do cenário) + risco Canadá do prompt
A3: SOFR 2026E alinhado a Fed terminal 3.0–3.25% | B3: Model | C3: S16 | D3: =AVERAGE(3.53%,3.32%,3.2%,3.16%) -> 0.033025 | E3: =[3]Model!S16 -> 0.0315 | F3: SOFR 2026E alinhado a Fed terminal 3.0–3.25% (mid 3.15%) | G3: premissas macro do prompt
A4: TH SSS 2026E ligeiramente acima | B4: Model | C4: S74 | D4: 0.02 | E4: =[3]Model!S74 -> 0.021 | F4: TH SSS 2026E ligeiramente acima (macro ok), mas sem exagero por headwind Canadá | G4: premissas macro do prompt
A5: BK SSS 2026E acima do base por PIB EUA 2.5% e execução | B5: Model | C5: S133 | D5: 0.02 | E5: =[3]Model!S133 -> 0.025 | F5: BK SSS 2026E acima do base por PIB EUA 2.5% e execução | G5: premissas macro do prompt
A6: BK net new franchise units (#) 2026E | B6: Model | C6: S124 | D6: 500 | E6: =[3]Model!S124 -> 550 | F6: BK net new franchise units (#) 2026E: step-up ligado ao plano China (ramp) | G6: https://www.rbi.com/English/news/news-details/2025/RBI-and-CPE-Announce-Joint-Venture-to-Reignite-Growth-at-Burger-King-in-China/default.aspx
A7: Popeyes SSS 2026E | B7: Model | C7: S190 | D7: 0.035 | E7: =[3]Model!S190 -> 0.04 | F7: Popeyes SSS 2026E: maior tração do 'chicken war' + macro EUA | G7: premissas macro do prompt
A8: Popeyes net new franchise units (#) 2026E | B8: Model | C8: S181 | D8: 400 | E8: =[3]Model!S181 -> 420 | F8: Popeyes net new franchise units (#) 2026E: leve aceleração | G8: premissas macro do prompt
A9: Firehouse SSS 2026E | B9: Model | C9: S247 | D9: 0.015 | E9: =[3]Model!S247 -> 0.017 | F9: Firehouse SSS 2026E: comps estáveis com macro favorável | G9: premissas macro do prompt
A10: Payout 2026E menor para reter caixa e investir | B10: Model | C10: S925 | D10: 0.5 | E10: =[3]Model!S925 -> 0.45 | F10: Payout 2026E menor para reter caixa e investir (China / crescimento) | G10: https://www.rbi.com/English/news/news-details/2025/RBI-and-CPE-Announce-Joint-Venture-to-Reignite-Growth-at-Burger-King-in-China/default.aspx
A11: Payout 2027E menor mantendo reinvestimento no ramp | B11: Model | C11: T925 | D11: 0.5 | E11: =[3]Model!T925 -> 0.45 | F11: Payout 2027E menor mantendo reinvestimento no ramp | G11: https://www.rbi.com/English/news/news-details/2025/RBI-and-CPE-Announce-Joint-Venture-to-Reignite-Growth-at-Burger-King-in-China/default.aspx
A12: Ke base reduzido | B12: Summary | C12: B95 | D12: 0.09 | E12: =[3]Summary!B95 -> 0.085 | F12: Ke base reduzido (CAPM proxy) vs 9% original, refletindo queda do risk-free | G12: premissas macro do prompt
A15: CAPM (para Ke)
A16: Risk-free (Rf) | B16: Model | C16: S16 | E16: 0.0437 | F16: Proxy: SOFR 2026E | G16: premissas macro do prompt
A17: Beta (β) [input] | E17: 0.63 | F17: Beta setorial (ajustável) | G17: definir fonte preferida
A18: Equity Risk Premium (ERP) [input] | E18: 0.06 | F18: ERP global (ajustável) | G18: definir fonte preferida
A19: Ke = Rf + β*ERP [calc] | E19: =E16+E17*E18 -> 0.0815 | F19: Ke calculado (confira) e aplicado em Summary!B95
A21: Nota: Não ajustei linhas de 'Acquisition of Franchisees' / dívida por falta de preço explícito da transação; payout foi reduzido para refletir maior reinvestimento e você pode plugar o ticket quando tiver disclosure.

Sheet UNITS
B1: Global Store Counts Across Brands by Countries and Territories as of December 31, 2025
B3: Countries and Territories | C3: Tim Hortons | D3: Burger King | E3: Popeyes | F3: Firehouse | G3: Total
B4: Albania | C4: 0 | D4: 13 | E4: 1 | F4: 1 | G4: 15
B5: Andorra | C5: 2 | D5: 4 | E5: 3 | F5: 0 | G5: 9
B6: Argentina | C6: 0 | D6: 112 | E6: 0 | F6: 0 | G6: 112
B7: Armenia | C7: 0 | D7: 5 | E7: 0 | F7: 0 | G7: 5
B8: Aruba | C8: 0 | D8: 4 | E8: 0 | F8: 0 | G8: 4
B9: Australia | C9: 0 | D9: 480 | E9: 0 | F9: 0 | G9: 480
B10: Austria | C10: 0 | D10: 63 | E10: 0 | F10: 0 | G10: 63
B11: Azerbaijan | C11: 0 | D11: 7 | E11: 0 | F11: 0 | G11: 7
B12: Bahrain | C12: 9 | D12: 1 | E12: 4 | F12: 0 | G12: 14
B13: Bangladesh | C13: 0 | D13: 8 | E13: 0 | F13: 0 | G13: 8
B14: Barbados | C14: 0 | D14: 7 | E14: 0 | F14: 0 | G14: 7
B15: Belarus | C15: 0 | D15: 56 | E15: 0 | F15: 0 | G15: 56
... B133: Vietnam | C133: 0 | D133: 20 | E133: 62 | F133: 0 | G133: 82
B134: Total | C134: =SUM(C4:C133) -> 6232 | D134: =SUM(D4:D133) -> 19900 | E134: =SUM(E4:E133) -> 5413 | F134: =SUM(F4:F133) -> 1496 | G134: =SUM(G4:G133) -> 33041
B136: 1. Units physically located in LAC, EMEA and APAC that are managed by the US.

Sheet Planilha1
A1: 25
A2: 25
A3: 90
A6: 97
A7: 3

Sheet Planilha2
B1: 2024 | C1: 2025 | I1: 2024 | J1: 2025
A2: RBI | B2: 8406 | C2: 13623.702 | H2: RBI | I2: =B2/(WACC!V68/1000) -> 261.73055 | J2: =C2/(UNITS!G134/1000) -> 412.32716 | K2: =I2/I3 -> 0.43419805
A3: Mc Donald's | B3: 25920 | C3: 26685 | E3: =C2/C3 -> 0.51053782 | F3: =E3/E4-1 -> 0.57424939 | H3: Mc Donald's | I3: =B3/(43000/1000) -> 602.7907 | J3: =C3/(45000/1000) -> 593 | K3: =J2/J3 -> 0.69532406
E4: =B2/B3 -> 0.32430556 | F4: =B2/B3 -> 0.32430556 | K4: =(K3/K2)^(1/2)-1 -> 0.2654637
B27: 2590.5252 | C27: 1852.3798 | D27: 2556.7006 | E27: 3054.1387 | F27: 3677.5837 | G27: 4504.8279 | H27: 5552.3754 | J27: 33859.06
B28: =B27/$J$27 -> 0.07650907 | C28: =C27/$J$27 -> 0.054708541 | D28: =D27/$J$27 -> 0.075510089 | E28: =E27/$J$27 -> 0.090201521 | F28: =F27/$J$27 -> 0.10861447 | G28: =G27/$J$27 -> 0.13304645 | H28: =H27/$J$27 -> 0.16398492
M29: 2985.2952
B30: 2025 | C30: =B27/$J$27 -> 0.07650907 | M30: -309.11145
B31: 2026 | C31: =C27/$J$27 -> 0.054708541 | M31: -268
B32: 2027 | C32: =D27/$J$27 -> 0.075510089 | M32: -360
B33: 2028 | C33: =E27/$J$27 -> 0.090201521 | M33: =M29+SUM(M30:M32) -> 2048.1838 | N33: =M33/M29 -> 0.68609086
B34: 2029 | C34: =F27/$J$27 -> 0.10861447 | M34: =M33-SUM(M30:M31) -> 2625.2952 | N34: =1-M34/M29 -> 0.12059109
B35: 2030 | C35: =G27/$J$27 -> 0.13304645
B36: 2031 | C36: =H27/$J$27 -> 0.16398492 | L36: EBIT | M36: =Model!R544 -> 2547.9744
L37: Financial Result | M37: =Model!R548 -> -711.22819
L38: CAPEX | M38: =Model!R742 -> -359.96815
L39: Working Capital | M39: =Model!R767-Model!Q767 -> 505.62448
L40: Free Cash Flow | M40: =SUM(M36:M39) -> 1982.4025
M49: CPE | N49: 0.83
M50: RBI | N50: 0.17
C57: 2024 | D57: 2025 | E57: 2026E | F57: 2027E | G57: 2028E | H57: 2029E | I57: 2030E | J57: 2031E
C58: =C59*$B$59 -> 22000 | D58: =D59*$B$59 -> 37000 | E58: =E59*$B$59 -> 38850 | F58: =F59*$B$59 -> 40792.5 | G58: =G59*$B$59 -> 42832.125 | H58: =H59*$B$59 -> 36407.306 | I58: =I59*$B$59 -> 30946.21 | J58: =J59*$B$59 -> 26304.279 | P58: 2024 | Q58: 2025 | R58: 2026E | S58: 2027E | T58: 2028E | U58: 2029E | V58: 2030E | W58: 2031E
B59: 1000 | C59: 22 | D59: 37 | E59: 38.85 | F59: 40.7925 | G59: 42.832125 | H59: 36.407306 | I59: 30.94621 | J59: 26.304279 | N59: =(J58/G58)^(1/4)-1 -> -0.11475355 | P59: 660 | Q59: 359.96815 | R59: 370.12196 | S59: 368.1518 | T59: 272.04763 | U59: 264.31981 | V59: 260.19247 | W59: 269.14565
